Workbook

Sheet file overview
A1: supplementary materials:
B3: CONSTRUCTING AND ANALYZING STOICHIOMETRIC MODELS OF NON-MODEL ORGANISMS: A CASE STUDY OF METHANOTROPHS AND GLOBAL WARMING POTENTIAL
B5: Adrienne D. Arnold, Campbell B. Putnam, Ashley E. Beck, Robin Gerlach, Ross P. Carlson
B7: tab
B8: model reaction data: experimental justification for model reactions
B9: biomass composition: conversion of experimental biomass composition data into a systems biology representation
B10: biomass calculations: manipulates the biomass composition for degree of reduction, carbon moles, and ATP requirements
B11: biomass reaction variations: list of biomass synthesis reactions considering different biomass degrees of reduction and different growth associated maintenance energy
B12: model metabolite data: analysis of model metabolites for elemental composition, charge, and degree of reduction
B13: model balance analysis: demonstration of mass balance, including electron balance, for the metabolic model using the stoichiometric matrix and metabolite chemical matrix
B14: CNA inputs type I: cellnetanalyzer syntax for defining 'reactions' and 'metabolites' files for the type I methanotroph simulations
B15: CNA inputs type II: cellnetanalyzer syntax for defining 'reactions' and 'metabolites' files for the type II methanotroph simulations
B16: ATP summary: summary of metabolic modeling results for type I and type II methanotroph ATP generation as a function of O2 and nitrate
... B25: code summary: summary of the CellNetAnalyzer and Flux Balance Analysis files and code

Sheet model reaction data
C2: type I or type II? | D2: rxn number | E2: pathway | F2: reaction | G2: reaction from metacyc | H2: reverse | I2: forward | J2: compartment | K2: EC number | L2: full name | M2: type I example gene | N2: type II example gene | Q2: copper cost | R2: citation
C3: both | D3: R1 | E3: methane metabolism | F3: methane + QH2 + O2 = methanol + Q + H2O | G3: methane + an electron-transfer quinol + dioxygen → methanol + an electron-transfer quinone + H2O | H3: 0 | I3: 1000 | J3: membrane bound | K3: 1.14.18.3 | L3: methane monooxygenase (particulate) | Q3: 3
C4: both | D4: R2 | E4: methane metabolism | F4: methane + NADH + H+ + O2 = methanol + NAD+ + H2O | G4: methane + NAD(P)H + dioxygen + H+ → methanol + NAD(P)+ + H2O | H4: 0 | I4: 1000 | J4: cytoplasm | K4: 1.14.13.25 | L4: methane monooxygenase (soluble)
C5: both | D5: direct_coupling | E5: methane metabolism | F5: methane + O2 = formaldehyde + H2O | H5: 0 | I5: 1000 | J5: membrane bound | L5: direct coupling | Q5: 3
C6: both | D6: R3 | E6: methane metabolism | F6: methanol + 2 cytc = formaldehyde + 2 cytcE + 2 H_pmf | G6: methanol + 2 an oxidized cytochrome cL → formaldehyde + 2 a reduced cytochrome cL + 2 H+ | H6: 0 | I6: 1000 | J6: periplasmic space | K6: 1.1.2.7 | L6: cytochrome c methanol dehydrogenase
C8: both | D8: R4 | E8: formaldehyde oxidation | F8: formaldehyde + NAD+ + H2O = formate + NADH + 2 H+ | G8: formaldehyde + NAD+ + H2O → formate + NADH + 2 H+ | H8: 0 | I8: 1000 | J8: cytoplasm | K8: 1.2.1.46 | L8: formaldehyde dehydrogenase
C9: both | D9: R5 | E9: formaldehyde oxidation | F9: formaldehyde + 2 cytc + H2O = formate + 2 cytcE + 3 H_pmf | G9: formaldehyde + 2 ferricytochrome b559/569 + H2O = formate + 2 ferrocytochrome b559/569 + 2 H+ | H9: 0 | I9: 1000 | J9: membrane | K9: 1.2.2.B1 | L9: quinoprotein formaldehyde dehydrogenase (cytochrome b559/569)
C11: I | D11: R6 | E11: ribulose monophosphate pathway (RuMP) | F11: D-ribulose_5-phosphate + formaldehyde = hexulose_6-phosphate | G11: hexulose 6-phosphate ↔ D-ribulose 5-phosphate + formaldehyde | H11: -1000 | I11: 1000 | K11: 4.1.2.43 | L11: 3-hexulose-6-phosphate synthase
C12: I | D12: R7 | E12: ribulose monophosphate pathway (RuMP) | F12: hexulose_6-phosphate = B-D-fructofuranose_6-phosphate | G12: hexulose 6-phosphate ↔ β-D-fructofuranose 6-phosphate | H12: -1000 | I12: 1000 | K12: 5.3.1.27 | L12: 6-phospho-3-hexuloisomerase
C14: both | D14: R8 | E14: formaldehyde oxidation (H4MPT) pathway | F14: formaldehyde + tetrahydromethanopterin = H2O + 5,10-methylene-tetrahydromethanopterin | G14: 5,10-methylene-tetrahydromethanopterin + H2O ← formaldehyde + tetrahydromethanopterin | H14: 0 | I14: 1000 | K14: 4.2.1.147 | L14: 5,6,7,8-tetrahydromethanopterin hydro-lyase
C15: both | D15: R9 | E15: formaldehyde oxidation (H4MPT) pathway | F15: 5,10-methylene-tetrahydromethanopterin + NAD+ = 5,10-methenyltetrahydromethanopterin + NADH | G15: 5,10-methylene-tetrahydromethanopterin + NAD(P)+ ↔ 5,10-methenyltetrahydromethanopterin + NAD(P)H | H15: 0 | I15: 1000 | K15: 1.5.1.- | L15: NAD(P)-dependent methylene H4MPT dehydrogenase
C16: both | D16: R10 | E16: formaldehyde oxidation (H4MPT) pathway | F16: 5,10-methylene-tetrahydromethanopterin + NADP+ = 5,10-methenyltetrahydromethanopterin + NADPH | G16: 5,10-methylene-tetrahydromethanopterin + NAD(P)+ ↔ 5,10-methenyltetrahydromethanopterin + NAD(P)H | H16: 0 | I16: 1000 | K16: 1.5.1.- | L16: NAD(P)-dependent methylene H4MPT dehydrogenase
C17: both | D17: R11 | E17: formaldehyde oxidation (H4MPT) pathway | F17: 5,10-methenyltetrahydromethanopterin + H2O = 5-formyl-tetrahydromethanopterin + H+ | G17: 5,10-methenyltetrahydromethanopterin + H2O → 5-formyl-tetrahydromethanopterin + H+ | H17: -1000 | I17: 1000 | K17: 3.5.4.27 | L17: methenyltetrahydropterin cyclohydrolase
C18: both | D18: R12 | E18: formaldehyde oxidation (H4MPT) pathway | F18: 5-formyl-tetrahydromethanopterin + H2O = formate + tetrahydromethanopterin + H+ | G18: 5-formyl-tetrahydromethanopterin + H2O → formate + tetrahydromethanopterin + H+ | H18: 0 | I18: 1000 | K18: N/A | L18: formyltransferase/hydrolase complex
C20: both | D20: R13 | E20: formaldehyde oxidation (THF) pathway | F20: formaldehyde + tetrahydrofolate = 5,10-methylenetetrahydrofolate + H2O | H20: 0 | I20: 1000 | K20: spontaneous | L20: spontaneous
C21: both | D21: R14 | E21: formaldehyde oxidation (THF) pathway | F21: 5,10-methylenetetrahydrofolate + NADP+ = 5,10-methenyltetrahydrofolate + NADPH | G21: 5,10-methylenetetrahydrofolate + NADP+ → 5,10-methenyltetrahydrofolate + NADPH | H21: 0 | I21: 1000 | K21: 1.5.1.5. | L21: methylenetetrahydrofolate dehydrogenase (NADP+)
C22: type II | D22: R15 | E22: formaldehyde oxidation (THF) pathway | F22: 5,10-methenyltetrahydrofolate + H2O = 10-formyl-tetrahydrofolate + H+ | G22: 5,10-methenyltetrahydrofolate + H2O ↔ 10-formyl-tetrahydrofolate + H+ | H22: -1000 | I22: 1000 | K22: 3.5.4.9 | L22: methenyl tetrahydrofolate cyclohydrolase
C23: both | D23: R16 | E23: formaldehyde oxidation (THF) pathway | F23: ATP + formate + tetrahydrofolate = ADP + 10-formyl-tetrahydrofolate + phosphate | G23: ATP + formate + tetrahydrofolate ↔ ADP + 10-formyl-tetrahydrofolate + phosphate | H23: -1000 | I23: 1000 | K23: 6.3.4.3 | L23: formate-tetrahydrofolate ligase
C25: both | D25: R17 | E25: formate dehydrogenase | F25: formate + NAD+ = NADH + CO2 | G25: formate + NAD+ ⇄ CO2 + NADH | H25: 0 | I25: 1000 | K25: 1.17.1.9 | L25: formate dehydrogenase
A27: other functionality in type I methanotrophs But et al 2019 | C27: both | D27: R18 | E27: serine cycle | F27: glycine + 5,10-methylenetetrahydrofolate + H2O = L-serine + tetrahydrofolate | G27: L-serine + a tetrahydrofolate ↔ glycine + a 5,10-methylenetetrahydrofolate + H2O | H27: -1000 | I27: 1000 | K27: 2.1.2.1 | L27: glycine hydroxymethyltransferase (serine hydroxymethyltransferase)
A28: also annotated as alanine, check But et al 2019 | C28: both | D28: R19 | E28: serine cycle | F28: glyoxylate + L-serine = glycine + hydroxypyruvate | G28: glyoxylate + L-serine ↔ hydroxypyruvate + glycine | H28: -1000 | I28: 1000 | K28: 2.6.1.45 | L28: serine-glyoxylate aminotransferase
B29: But et al 2017, need both NADH and NADPH versions of this. Also it's tetrameric in OB3b but dimeric in methanotrophs w the RuMP pathway. Also, for type I or type X methanotrophs, plays a role in interconversion of glyoxylate and glycolate--less important for type II, consider whether to add it in (But et al 2017). Irreversible in methanotrophs both for glycerate to hydroxypyruvate and for glycolate oxidation | C29: both | D29: R20 | E29: serine cycle | F29: hydroxypyruvate + NADH + H+ = D-glycerate + NAD+ | G29: D-glycerate + NAD(P)+ ↔ hydroxypyruvate + NAD(P)H + H+ | H29: 0 | I29: 1000 | K29: 1.1.1.81 | L29: hydroxypyruvate reductase
B30: But et al 2017 | C30: both | D30: R21 | E30: serine cycle | F30: hydroxypyruvate + NADPH + H+ = D-glycerate + NADP+ | G30: D-glycerate + NAD(P)+ ↔ hydroxypyruvate + NAD(P)H + H+ | H30: 0 | I30: 1000 | K30: 1.1.1.81 | L30: hydroxypyruvate reductase
C31: both | D31: R22 | E31: serine cycle | F31: D-glycerate + ATP = 2-phospho-D-glycerate + ADP + H+ | G31: D-glycerate + ATP → 2-phospho-D-glycerate + ADP + H+ | H31: 0 | I31: 1000 | K31: 2.7.1.165 | L31: glycerate kinase
C32: both | D32: R23 | E32: serine cycle to gluconeogenesis | F32: 2-phospho-D-glycerate = 3-phospho-D-glycerate | G32: 2-phospho-D-glycerate ↔ 3-phospho-D-glycerate | H32: -1000 | I32: 1000 | K32: 5.4.2.12 | L32: 2,3-bisphosphoglycerate-independent phosphoglycerate mutase
C33: both | D33: R24 | E33: serine cycle to gluconeogenesis | F33: 2-phospho-D-glycerate = phosphoenolpyruvate + 1 H2O | G33: 2-phospho-D-glycerate ↔ phosphoenolpyruvate + H2O | H33: -1000 | I33: 1000 | K33: 4.2.1.11 | L33: enolase
B34: OAA reduction is favored vs malate oxidation in OB3b, Rozova 2015 | C34: II | D34: R25 | E34: serine cycle | F34: phosphoenolpyruvate + hydrogencarbonate = oxaloacetate + phosphate | G34: oxaloacetate + phosphate ← phosphoenolpyruvate + hydrogencarbonate | H34: 0 | I34: 1000 | K34: 4.1.1.31 | L34: phosphoenolpyruvate carboxylase
C35: both | D35: R26 | E35: serine cycle to TCA | F35: oxaloacetate + NADH + H+ = (S)-malate + NAD+ | G35: (S)-malate + NAD+ ↔ oxaloacetate + NADH + H+ | H35: -1000 | I35: 1000 | K35: 1.1.1.37 | L35: malate dehydrogenase (NAD+)
C36: both | D36: R27 | E36: serine cycle | F36: (S)-malate + ATP + coenzyme_A = (S)-malyl-CoA + ADP + phosphate | G36: (S)-malate + ATP + coenzyme A ↔ (S)-malyl-CoA + ADP + phosphate | H36: -1000 | I36: 1000 | K36: 6.2.1.9 | L36: malate thiokinase (malate-CoA ligase)
A37: made irreversible to prevent loops. This means the EMC pathway can only be used to provide glyoxylate for the serine pathway, so glyoxylate cannot be converted to malate (without the addition of a 1C donor) | C37: both | D37: R28 | E37: serine cycle/EMC pathway | F37: (S)-malyl-CoA = acetyl-CoA + glyoxylate | G37: (S)-malyl-CoA ↔ glyoxylate + acetyl-CoA | H37: -1000 | I37: 1000 | K37: 4.1.3.24 | L37: malyl coenzyme A lyase
C39: II | D39: R29 | E39: EMC pathway/ PHB biosynthesis | F39: 2 acetyl-CoA = acetoacetyl-CoA + coenzyme_A | G39: 2 acetyl-CoA ↔ acetoacetyl-CoA + coenzyme A | H39: -1000 | I39: 1000 | K39: 2.3.1.9 | L39: acetyl-CoA acetyltransferase
C40: II | D40: R30 | E40: EMC pathway/ PHB biosynthesis | F40: acetoacetyl-CoA + NADPH + H+ = (3R)-3-hydroxybutanoyl-CoA + NADP+ | G40: (3R)-3-hydroxybutanoyl-CoA + NADP+ ← acetoacetyl-CoA + NADPH + H+ | H40: 0 | I40: 1000 | K40: 1.1.1.36 | L40: acetoacetyl-CoA reductase
C41: II | D41: R31 | E41: EMC pathway | F41: (3R)-3-hydroxybutanoyl-CoA = crotonyl-CoA + H2O | G41: (3R)-3-hydroxybutanoyl-CoA ↔ crotonyl-CoA + H2O | H41: -1000 | I41: 1000 | K41: 4.2.1.55 | L41: 3-hydroxybutyryl-CoA dehydratase (crotonase)
C42: II | D42: R32 | E42: EMC pathway | F42: crotonyl-CoA + CO2 + NADPH = NADP+ + (2S)-ethylmalonyl-CoA | G42: (2S)-ethylmalonyl-CoA + NADP+ ← crotonyl-CoA + CO2 + NADPH | H42: 0 | I42: 1000 | K42: 1.3.1.85 | L42: crotonyl-CoA carboxylase/reductase
C43: II | D43: R33 | E43: EMC pathway | F43: (2S)-ethylmalonyl-CoA = (2R)-ethylmalonyl-CoA | G43: (2S)-ethylmalonyl-CoA → (2R)-ethylmalonyl-CoA | H43: 0 | I43: 1000 | K43: 5.1.99.1 | L43: ethylmalonyl-CoA/methylmalonyl-CoA epimerase
C44: II | D44: R34 | E44: EMC pathway | F44: (2R)-ethylmalonyl-CoA = (2S)-methylsuccinyl-CoA | G44: (2R)-ethylmalonyl-CoA → (2S)-methylsuccinyl-CoA | H44: 0 | I44: 1000 | K44: 5.4.99.63 | L44: (2R)-ethylmalonyl-CoA mutase
A45: flavoprotein converted to quinol for purposes of this model | C45: II | D45: R35 | E45: EMC pathway | F45: (2S)-methylsuccinyl-CoA + Q = QH2 + 2-methylfumaryl-CoA | G45: (2S)-methylsuccinyl-CoA + an oxidized electron-transfer flavoprotein + H+ → 2-methylfumaryl-CoA + a reduced electron-transfer flavoprotein | H45: 0 | I45: 1000 | K45: 1.3.8.12 | L45: (2S)-methylsuccinyl-CoA dehydrogenase
C46: II | D46: R36 | E46: EMC pathway | F46: 2-methylfumaryl-CoA + H2O = (2R,3S)-B-methylmalyl-CoA | G46: (2R,3S)-β-methylmalyl-CoA ↔ 2-methylfumaryl-CoA + H2O | H46: -1000 | I46: 1000 | K46: 4.2.1.148 | L46: mesaconyl-CoA hydratase
C47: II | D47: R38 | E47: EMC pathway to propanoyl CoA degradation | F47: (2R,3S)-B-methylmalyl-CoA = glyoxylate + propanoyl-CoA | G47: (2R,3S)-β-methylmalyl-CoA ↔ glyoxylate + propanoyl-CoA | H47: -1000 | I47: 1000 | K47: 4.1.3.24 | L47: malyl-CoA lyase
C49: II | D49: R39 | E49: propanoyl CoA degradation | F49: ATP + propanoyl-CoA + hydrogencarbonate = (S)-methylmalonyl-CoA + ADP + phosphate + H+ | G49: ATP + propanoyl-CoA + hydrogencarbonate ↔ (S)-methylmalonyl-CoA + ADP + phosphate + H+ | H49: -1000 | I49: 1000 | K49: 6.4.1.3 | L49: propanoyl-CoA carboxylase
...

Sheet type II biomass composition
A2: Biomass term calculation sheet: | C2: (based on theory from Neidhardt et al., 1990, Physiology of the Bacterial Cell)
A4: biomass composition values from Yang et al., 2013 for Methylosinus trichosporium OB3b DOI 10.3389/fmicb.2013.00070 | AA4: weighted cost
A5: protein
B6: molecular weight (g/mol) | C6: % cdw (w/w) (values from Yang et al 2013) | D6: final mol compound/ mol biomass | E6: calculated % cdw g/g from Neidhardt | F6: umol / g (from Neidhardt pg 136) | G6: DNA and RNA (molar fractions) from GC content and from 16S rRNA | I6: glc-6-p | J6: rib-5-p | K6: ery-4-p | L6: pep | M6: pyr | N6: ace-coa | O6: akg | P6: oxalo | Q6: atp | R6: nadh | S6: nadph | T6: N_GT | U6: NH4 | V6: N_GN | W6: CO2 | X6: polyhydroxybutyrate_produced/glycogen_produced | Y6: L-ornithine | AA6: glc-6-p | AB6: rib-5-p | AC6: ery-4-p | AD6: pep | AE6: pyr | AF6: ace-coa | AG6: akg | AH6: oxalo | AI6: atp | AJ6: nadh | AK6: nadph | AL6: N_GLU | AM6: N_GLN | AN6: co2 | AO6: polyhydroxybutyrate | AP6: L-ornithine | AU6: glc-6-p | AV6: rib-5-p | AW6: ery-4-p | AX6: pep | AY6: pyr | AZ6: ace-coa | BA6: akg | BB6: oxalo | BC6: atp | BD6: nadh | BE6: nadph | BF6: N_GLU | BG6: N_GLN | BH6: CO2 | BI6: polyhydroxybutyrate | BJ6: L-ornithine | BM6: polymerization ATP | BN6: polymerization ATP mol/mol | BP6: *accounts for ATP required to polymerize proteins, RNA, DNA, etc.
A7: alanine | B7: 89.09 | C7: 4.7 | D7: =(C7/100)*24*(1/B7) -> 0.012661354 | E7: =((F7*B7*(10^(-6)))/1)*100 -> 4.347592 | F7: 488 | M7: 1 | S7: 0 | T7: 1 | AA7: =I7*D7 -> 0 | AB7: =J7*D7 -> 0 | AC7: =K7*D7 -> 0 | AD7: =L7*D7 -> 0 | AE7: =M7*D7 -> 0.012661354 | AF7: =N7*D7 -> 0 | AG7: =O7*D7 -> 0 | AH7: =P7*D7 -> 0 | AI7: =Q7*D7 -> 0 | AJ7: =R7*D7 -> 0 | AK7: =D7*S7 -> 0 | AL7: =T7*D7 -> 0.012661354 | AM7: =V7*D7 -> 0 | AN7: =D7*W7 -> 0 | AO7: =$D7*X7 -> 0 | AP7: =$D7*Y7 -> 0
A8: arginine | B8: 174.2 | C8: 5.2 | D8: =(C8/100)*24*(1/B8) -> 0.0071641791 | E8: =((F8*B8*(10^(-6)))/1)*100 -> 4.89502 | F8: 281 | O8: 1 | Q8: 6 | R8: -1 | S8: 1 | T8: 3 | V8: 1 | AA8: =I8*D8 -> 0 | AB8: =J8*D8 -> 0 | AC8: =K8*D8 -> 0 | AD8: =L8*D8 -> 0 | AE8: =M8*D8 -> 0 | AF8: =N8*D8 -> 0 | AG8: =O8*D8 -> 0.0071641791 | AH8: =P8*D8 -> 0 | AI8: =Q8*D8 -> 0.042985075 | AJ8: =R8*D8 -> -0.0071641791 | AK8: =D8*S8 -> 0.0071641791 | AL8: =T8*D8 -> 0.021492537 | AM8: =V8*D8 -> 0.0071641791 | AN8: =D8*W8 -> 0 | AO8: =$D8*X8 -> 0 | AP8: =$D8*Y8 -> 0
A9: asparagine | B9: 132.12 | C9: 1.6 | D9: =(C9/100)*24*(1/B9) -> 0.0029064487 | E9: =((F9*B9*(10^(-6)))/1)*100 -> 3.025548 | F9: 229 | P9: 1 | Q9: 2 | S9: 0 | T9: 1 | V9: 1 | AA9: =I9*D9 -> 0 | AB9: =J9*D9 -> 0 | AC9: =K9*D9 -> 0 | AD9: =L9*D9 -> 0 | AE9: =M9*D9 -> 0 | AF9: =N9*D9 -> 0 | AG9: =O9*D9 -> 0 | AH9: =P9*D9 -> 0.0029064487 | AI9: =Q9*D9 -> 0.0058128974 | AJ9: =R9*D9 -> 0 | AK9: =D9*S9 -> 0 | AL9: =T9*D9 -> 0.0029064487 | AM9: =V9*D9 -> 0.0029064487 | AN9: =D9*W9 -> 0 | AO9: =$D9*X9 -> 0 | AP9: =$D9*Y9 -> 0 | AT9: sumProt: | AU9: =AA28 -> 0 | AV9: =AB28 -> 0.003575821 | AW9: =AC28 -> 0.0082726577 | AX9: =AD28 -> 0.031136596 | AY9: =AE28 -> 0.057811686 | AZ9: =AF28 -> 0.009880308 | BA9: =AG28 -> 0.021531454 | BB9: =AH28 -> 0.026020312 | ... BJ9: =AP28 -> 0 | BM9: 22000 | BN9: =BM9*24*(1/(10^6)) -> 0.528
A10: aspartate | B10: 133.11 | C10: 3.2 | D10: =(C10/100)*24*(1/B10) -> 0.0057696642 | E10: =((F10*B10*(10^(-6)))/1)*100 -> 3.048219 | F10: 229 | P10: 1 | S10: 0 | T10: 1 | AA10: =I10*D10 -> 0 | AB10: =J10*D10 -> 0 | AC10: =K10*D10 -> 0 | AD10: =L10*D10 -> 0 | AE10: =M10*D10 -> 0 | AF10: =N10*D10 -> 0 | AG10: =O10*D10 -> 0 | AH10: =P10*D10 -> 0.0057696642 | AI10: =Q10*D10 -> 0 | AJ10: =R10*D10 -> 0 | AK10: =D10*S10 -> 0 | AL10: =T10*D10 -> 0.0057696642 | AM10: =V10*D10 -> 0 | AN10: =D10*W10 -> 0 | AO10: =$D10*X10 -> 0 | AP10: =$D10*Y10 -> 0 | AT10: sumRNA: | AU10: =AA36 -> 0 | AV10: =AB36 -> 0.0096894335 | AW10: =AC36 -> 0 | AX10: =AD36 -> 0.0046797902 | AY10: =AE36 -> 0 | AZ10: =AF36 -> 0 | BA10: =AG36 -> 0 | BB10: =AH36 -> 0.0050096433 | ... BJ10: =AP36 -> 0 | BM10: 256 | BN10: =BM10*24*(1/(10^6)) -> 0.006144
A11: cysteine | B11: 121.16 | C11: 0.4 | D11: =(C11/100)*24*(1/B11) -> 0.00079234071 | E11: =((F11*B11*(10^(-6)))/1)*100 -> 1.054092 | F11: 87 | L11: 1 | Q11: 4 | R11: -1 | S11: 4 | T11: 1 | AA11: =I11*D11 -> 0 | AB11: =J11*D11 -> 0 | AC11: =K11*D11 -> 0 | AD11: =L11*D11 -> 0.00079234071 | AE11: =M11*D11 -> 0 | AF11: =N11*D11 -> 0 | AG11: =O11*D11 -> 0 | AH11: =P11*D11 -> 0 | AI11: =Q11*D11 -> 0.0031693628 | AJ11: =R11*D11 -> -0.00079234071 | AK11: =D11*S11 -> 0.0031693628 | AL11: =T11*D11 -> 0.00079234071 | AM11: =V11*D11 -> 0 | AN11: =D11*W11 -> 0 | AO11: =$D11*X11 -> 0 | AP11: =$D11*Y11 -> 0 | AT11: sumDNA: | AU11: =AA43 -> 0 | AV11: =AB43 -> 0.0014910151 | AW11: =AC43 -> 0 | AX11: =AD43 -> 0.00074550754 | AY11: =AE43 -> 0 | AZ11: =AF43 -> 0 | BA11: =AG43 -> 0 | BB11: =AH43 -> 0.00074550754 | ... BJ11: =AP43 -> 0 | BM11: 150 | BN11: =BM11*24*(1/(10^6)) -> 0.0036
A12: glutamate | B12: 147.13 | C12: 3.7 | D12: =(C12/100)*24*(1/B12) -> 0.0060354788 | E12: =((F12*B12*(10^(-6)))/1)*100 -> 3.67825 | F12: 250 | O12: 1 | S12: 0 | T12: 1 | AA12: =I12*D12 -> 0 | AB12: =J12*D12 -> 0 | AC12: =K12*D12 -> 0 | AD12: =L12*D12 -> 0 | AE12: =M12*D12 -> 0 | AF12: =N12*D12 -> 0 | AG12: =O12*D12 -> 0.0060354788 | AH12: =P12*D12 -> 0 | AI12: =Q12*D12 -> 0 | AJ12: =R12*D12 -> 0 | AK12: =D12*S12 -> 0 | AL12: =T12*D12 -> 0.0060354788 | AM12: =V12*D12 -> 0 | AN12: =D12*W12 -> 0 | AO12: =$D12*X12 -> 0 | AP12: =$D12*Y12 -> 0 | AT12: sumLipd: | AU12: =AA49 -> 0 | AV12: =AB49 -> 0 | AW12: =AC49 -> 0 | AX12: =AD49 -> 0.0055396936 | AY12: =AE49 -> 0 | AZ12: =AF49 -> 0.044317549 | BA12: =AG49 -> 0 | BB12: =AH49 -> 0 | ... BJ12: =AP49 -> 0 | BM12: 258 | BN12: =BM12*24*(1/(10^6)) -> 0.006192
A13: glutamine | B13: 146.14 | C13: 1.9 | D13: =(C13/100)*24*(1/B13) -> 0.0031202956 | E13: =((F13*B13*(10^(-6)))/1)*100 -> 3.6535 | F13: 250 | O13: 1 | Q13: 0 | S13: 0 | T13: 1 | V13: 1 | AA13: =I13*D13 -> 0 | AB13: =J13*D13 -> 0 | AC13: =K13*D13 -> 0 | AD13: =L13*D13 -> 0 | AE13: =M13*D13 -> 0 | AF13: =N13*D13 -> 0 | AG13: =O13*D13 -> 0.0031202956 | AH13: =P13*D13 -> 0 | AI13: =Q13*D13 -> 0 | AJ13: =R13*D13 -> 0 | AK13: =D13*S13 -> 0 | AL13: =T13*D13 -> 0.0031202956 | AM13: =V13*D13 -> 0.0031202956 | AN13: =D13*W13 -> 0 | AO13: =$D13*X13 -> 0 | AP13: =$D13*Y13 -> 0 | AT13: sumLPS: | AU13: =AA59 -> 0.001033446 | AV13: =AB59 -> 0.00036438082 | AW13: =AC59 -> 0 | AX13: =AD59 -> 0.00072876165 | AY13: =AE59 -> 0 | AZ13: =AF59 -> 0.0051013315 | BA13: =AG59 -> 0 | BB13: =AH59 -> 0 | ... BJ13: =AP59 -> 0 | BN13: =BM13*24*(1/(10^6)) -> 0
A14: glycine | B14: 75.07 | C14: 2.9 | D14: =(C14/100)*24*(1/B14) -> 0.0092713467 | E14: =((F14*B14*(10^(-6)))/1)*100 -> 4.369074 | F14: 582 | L14: 1 | R14: -1 | S14: 0 | T14: 1 | W14: -1 | AA14: =I14*D14 -> 0 | AB14: =J14*D14 -> 0 | AC14: =K14*D14 -> 0 | AD14: =L14*D14 -> 0.0092713467 | AE14: =M14*D14 -> 0 | AF14: =N14*D14 -> 0 | AG14: =O14*D14 -> 0 | AH14: =P14*D14 -> 0 | AI14: =Q14*D14 -> 0 | AJ14: =R14*D14 -> -0.0092713467 | AK14: =D14*S14 -> 0 | AL14: =T14*D14 -> 0.0092713467 | AM14: =V14*D14 -> 0 | AN14: =D14*W14 -> -0.0092713467 | AO14: =$D14*X14 -> 0 | AP14: =$D14*Y14 -> 0 | AT14: sumPpGl: | AU14: =AA67 -> 0.00080122409 | AV14: =AB67 -> 0 | AW14: =AC67 -> 0 | AX14: =AD67 -> 0.00040061205 | AY14: =AE67 -> 0.0012018361 | AZ14: =AF67 -> 0.00080122409 | BA14: =AG67 -> 0.00040061205 | BB14: =AH67 -> 0.00040061205 | ... BJ14: =AP67 -> 0 | BM14: 138 | BN14: =BM14*24*(1/(10^6)) -> 0.003312
A15: histidine | B15: 155.15 | C15: 1.4 | D15: =(C15/100)*24*(1/B15) -> 0.0021656461 | E15: =((F15*B15*(10^(-6)))/1)*100 -> 1.39635 | F15: 90 | J15: 1 | Q15: 4 | R15: -3 | S15: 0 | T15: 1 | V15: 2 | W15: 1 | AA15: =I15*D15 -> 0 | AB15: =J15*D15 -> 0.0021656461 | AC15: =K15*D15 -> 0 | AD15: =L15*D15 -> 0 | AE15: =M15*D15 -> 0 | AF15: =N15*D15 -> 0 | AG15: =O15*D15 -> 0 | AH15: =P15*D15 -> 0 | AI15: =Q15*D15 -> 0.0086625846 | AJ15: =R15*D15 -> -0.0064969384 | AK15: =D15*S15 -> 0 | AL15: =T15*D15 -> 0.0021656461 | AM15: =V15*D15 -> 0.0043312923 | AN15: =D15*W15 -> 0.0021656461 | AO15: =$D15*X15 -> 0 | AP15: =$D15*Y15 -> 0 | AT15: sumPSch | AU15: =AA71 -> 0 | AV15: =AB71 -> 0 | AW15: =AC71 -> 0 | AX15: =AD71 -> 0 | AY15: =AE71 -> 0 | AZ15: =AF71 -> 0 | BA15: =AG71 -> 0 | BB15: =AH71 -> 0 | ... BJ15: =AP71 -> 0 | BN15: =BM15*24*(1/(10^6)) -> 0
A16: isoleucine | B16: 131.17 | C16: 2.9 | D16: =(C16/100)*24*(1/B16) -> 0.0053060913 | E16: =((F16*B16*(10^(-6)))/1)*100 -> 3.620292 | F16: 276 | M16: 1 | P16: 1 | Q16: 2 | S16: 4 | T16: 1 | W16: -1 | AA16: =I16*D16 -> 0 | AB16: =J16*D16 -> 0 | AC16: =K16*D16 -> 0 | AD16: =L16*D16 -> 0 | AE16: =M16*D16 -> 0.0053060913 | AF16: =N16*D16 -> 0 | AG16: =O16*D16 -> 0 | AH16: =P16*D16 -> 0.0053060913 | AI16: =Q16*D16 -> 0.010612183 | AJ16: =R16*D16 -> 0 | AK16: =D16*S16 -> 0.021224365 | AL16: =T16*D16 -> 0.0053060913 | AM16: =V16*D16 -> 0 | AN16: =D16*W16 -> -0.0053060913 | AO16: =$D16*X16 -> 0 | AP16: =$D16*Y16 -> 0 | AT16: sumCU | AU16: =AA75 -> 0 | AV16: =AB75 -> 0 | AW16: =AC75 -> 0 | AX16: =AD75 -> 0.0015986297 | AY16: =AE75 -> 0 | AZ16: =AF75 -> 0 | BA16: =AG75 -> 0 | BB16: =AH75 -> 0 | ... BJ16: =AP75 -> 0 | BN16: =BM16*24*(1/(10^6)) -> 0
A17: leucine | B17: 131.17 | C17: 5.4 | D17: =(C17/100)*24*(1/B17) -> 0.009880308 | E17: =((F17*B17*(10^(-6)))/1)*100 -> 5.614076 | F17: 428 | M17: 2 | N17: 1 | R17: -1 | S17: 1 | T17: 1 | AA17: =I17*D17 -> 0 | AB17: =J17*D17 -> 0 | AC17: =K17*D17 -> 0 | AD17: =L17*D17 -> 0 | AE17: =M17*D17 -> 0.019760616 | AF17: =N17*D17 -> 0.009880308 | AG17: =O17*D17 -> 0 | AH17: =P17*D17 -> 0 | AI17: =Q17*D17 -> 0 | AJ17: =R17*D17 -> -0.009880308 | AK17: =D17*S17 -> 0.009880308 | AL17: =T17*D17 -> 0.009880308 | AM17: =V17*D17 -> 0 | AN17: =D17*W17 -> 0 | AO17: =$D17*X17 -> 0 | AP17: =$D17*Y17 -> 0 | AT17: sumPA: | AU17: =AA79 -> 0 | AV17: =AB79 -> 0 | AW17: =AC79 -> 0 | AX17: =AD79 -> 0 | AY17: =AE79 -> 0 | AZ17: =AF79 -> 0 | BA17: =AG79 -> 0 | BB17: =AH79 -> 0 | ... BJ17: =AP79 -> 0.00072088308 | BN17: =BM17*24*(1/(10^6)) -> 0
A18: lysine | B18: 146.19 | C18: 2.5 | D18: =(C18/100)*24*(1/B18) -> 0.0041042479 | E18: =((F18*B18*(10^(-6)))/1)*100 -> 4.765794 | F18: 326 | M18: 1 | P18: 1 | Q18: 2 | S18: 2 | T18: 2 | AA18: =I18*D18 -> 0 | AB18: =J18*D18 -> 0 | AC18: =K18*D18 -> 0 | AD18: =L18*D18 -> 0 | AE18: =M18*D18 -> 0.0041042479 | AF18: =N18*D18 -> 0 | AG18: =O18*D18 -> 0 | AH18: =P18*D18 -> 0.0041042479 | AI18: =Q18*D18 -> 0.0082084958 | AJ18: =R18*D18 -> 0 | AK18: =D18*S18 -> 0.0082084958 | AL18: =T18*D18 -> 0.0082084958 | AM18: =V18*D18 -> 0 | AN18: =D18*W18 -> 0 | AO18: =$D18*X18 -> 0 | AP18: =$D18*Y18 -> 0 | BM18: =BM9+BM10+BM11+BM12+BM14 -> 22802 | BN18: =BM18*24*(1/(10^6)) -> 0.547248
A19: methionine | B19: 149.21 | C19: 1.3 | D19: =(C19/100)*24*(1/B19) -> 0.0020910127 | E19: =((F19*B19*(10^(-6)))/1)*100 -> 2.178466 | F19: 146 | P19: 1 | Q19: 7 | S19: 7 | T19: 1 | W19: 1 | AA19: =I19*D19 -> 0 | AB19: =J19*D19 -> 0 | AC19: =K19*D19 -> 0 | AD19: =L19*D19 -> 0 | AE19: =M19*D19 -> 0 | AF19: =N19*D19 -> 0 | AG19: =O19*D19 -> 0 | AH19: =P19*D19 -> 0.0020910127 | AI19: =Q19*D19 -> 0.014637089 | AJ19: =R19*D19 -> 0 | AK19: =D19*S19 -> 0.014637089 | AL19: =T19*D19 -> 0.0020910127 | AM19: =V19*D19 -> 0 | AN19: =D19*W19 -> 0.0020910127 | AO19: =$D19*X19 -> 0 | AP19: =$D19*Y19 -> 0 | AT19: Sum | AU19: =AU9+AU10+AU11+AU12+AU13+AU14+AU15+AU16+AU17 -> 0.0018346701 | AV19: =AV9+AV10+AV11+AV12+AV13+AV14+AV15+AV16+AV17 -> 0.01512065 | AW19: =AW9+AW10+AW11+AW12+AW13+AW14+AW15+AW16+AW17 -> 0.0082726577 | AX19: =AX9+AX10+AX11+AX12+AX13+AX14+AX15+AX16+AX17 -> 0.044829591 | AY19: =AY9+AY10+AY11+AY12+AY13+AY14+AY15+AY16+AY17 -> 0.059013522 | AZ19: =AZ9+AZ10+AZ11+AZ12+AZ13+AZ14+AZ15+AZ16+AZ17 -> 0.060100413 | BA19: =BA9+BA10+BA11+BA12+BA13+BA14+BA15+BA16+BA17 -> 0.021932066 | BB19: =BB9+BB10+BB11+BB12+BB13+BB14+BB15+BB16+BB17 -> 0.032176075 | ... BH19: =BH9+BH10+BH11+BH12+BH13+BH14+BH15+BH16+BH17 -> -0.0048954815 | BI19: =SUM(BI9:BI17) -> 0.0031914894 | BJ19: =SUM(BJ9:BJ17) -> 0.00072088308 | BM19: =BM18+BC19 -> 22802.251 | BN19: =BM19*24*(1/(10^6)) -> 0.54725404
A20: phenylalanine | B20: 165.19 | C20: 2.9 | D20: =(C20/100)*24*(1/B20) -> 0.0042133301 | E20: =((F20*B20*(10^(-6)))/1)*100 -> 2.907344 | F20: 176 | K20: 1 | L20: 2 | Q20: 1 | S20: 1 | T20: 1 | AA20: =I20*D20 -> 0 | AB20: =J20*D20 -> 0 | AC20: =K20*D20 -> 0.0042133301 | AD20: =L20*D20 -> 0.0084266602 | AE20: =M20*D20 -> 0 | AF20: =N20*D20 -> 0 | AG20: =O20*D20 -> 0 | AH20: =P20*D20 -> 0 | AI20: =Q20*D20 -> 0.0042133301 | AJ20: =R20*D20 -> 0 | AK20: =D20*S20 -> 0.0042133301 | AL20: =T20*D20 -> 0.0042133301 | AM20: =V20*D20 -> 0 | AN20: =D20*W20 -> 0 | AO20: =$D20*X20 -> 0 | AP20: =$D20*Y20 -> 0 | AT20: Sum | AU20: =AU19/($BN$19/100) -> 0.33525018 | AV20: =AV19/($BN$19/100) -> 2.7630039 | AW20: =AW19/($BN$19/100) -> 1.5116668 | AX20: =AX19/($BN$19/100) -> 8.1917332 | AY20: =AY19/($BN$19/100) -> 10.78357 | AZ20: =AZ19/($BN$19/100) -> 10.982178 | BA20: =BA19/($BN$19/100) -> 4.0076572 | BB20: =BB19/($BN$19/100) -> 5.8795501 | ... BJ20: =BJ19/($BN$19/100) -> 0.13172732 | BM20: =BM19/(BM19/100) -> 100 | BN20: =BN19/(BN19/100) -> 100
A21: proline | B21: 115.13 | C21: 2.5 | D21: =(C21/100)*24*(1/B21) -> 0.0052115 | E21: =((F21*B21*(10^(-6)))/1)*100 -> 2.41773 | F21: 210 | O21: 1 | Q21: 1 | S21: 2 | T21: 1 | AA21: =I21*D21 -> 0 | AB21: =J21*D21 -> 0 | AC21: =K21*D21 -> 0 | AD21: =L21*D21 -> 0 | AE21: =M21*D21 -> 0 | AF21: =N21*D21 -> 0 | AG21: =O21*D21 -> 0.0052115 | AH21: =P21*D21 -> 0 | AI21: =Q21*D21 -> 0.0052115 | AJ21: =R21*D21 -> 0 | AK21: =D21*S21 -> 0.010423 | AL21: =T21*D21 -> 0.0052115 | AM21: =V21*D21 -> 0 | AN21: =D21*W21 -> 0 | AO21: =$D21*X21 -> 0 | AP21: =$D21*Y21 -> 0
A22: serine | B22: 105.09 | C22: 2.6 | D22: =(C22/100)*24*(1/B22) -> 0.0059377676 | E22: =((F22*B22*(10^(-6)))/1)*100 -> 2.154345 | F22: 205 | L22: 1 | R22: -1 | S22: 0 | T22: 1 | AA22: =I22*D22 -> 0 | AB22: =J22*D22 -> 0 | AC22: =K22*D22 -> 0 | AD22: =L22*D22 -> 0.0059377676 | AE22: =M22*D22 -> 0 | AF22: =N22*D22 -> 0 | AG22: =O22*D22 -> 0 | AH22: =P22*D22 -> 0 | AI22: =Q22*D22 -> 0 | AJ22: =R22*D22 -> -0.0059377676 | AK22: =D22*S22 -> 0 | AL22: =T22*D22 -> 0.0059377676 | AM22: =V22*D22 -> 0 | AN22: =D22*W22 -> 0 | AO22: =$D22*X22 -> 0 | AP22: =$D22*Y22 -> 0
A23: threonine | B23: 119.12 | C23: 2.9 | D23: =(C23/100)*24*(1/B23) -> 0.0058428475 | E23: =((F23*B23*(10^(-6)))/1)*100 -> 2.870792 | F23: 241 | P23: 1 | Q23: 2 | S23: 2 | T23: 1 | AA23: =I23*D23 -> 0 | AB23: =J23*D23 -> 0 | AC23: =K23*D23 -> 0 | AD23: =L23*D23 -> 0 | AE23: =M23*D23 -> 0 | AF23: =N23*D23 -> 0 | AG23: =O23*D23 -> 0 | AH23: =P23*D23 -> 0.0058428475 | AI23: =Q23*D23 -> 0.011685695 | AJ23: =R23*D23 -> 0 | AK23: =D23*S23 -> 0.011685695 | AL23: =T23*D23 -> 0.0058428475 | AM23: =V23*D23 -> 0 | AN23: =D23*W23 -> 0 | AO23: =$D23*X23 -> 0 | AP23: =$D23*Y23 -> 0
A24: tryptophan | B24: 204.23 | C24: 1.2 | D24: =(C24/100)*24*(1/B24) -> 0.0014101748 | E24: =((F24*B24*(10^(-6)))/1)*100 -> 1.102842 | F24: 54 | J24: 1 | K24: 1 | L24: 1 | Q24: 4 | R24: -2 | S24: 2 | T24: 1 | V24: 1 | AA24: =I24*D24 -> 0 | AB24: =J24*D24 -> 0.0014101748 | AC24: =K24*D24 -> 0.0014101748 | AD24: =L24*D24 -> 0.0014101748 | AE24: =M24*D24 -> 0 | AF24: =N24*D24 -> 0 | AG24: =O24*D24 -> 0 | AH24: =P24*D24 -> 0 | AI24: =Q24*D24 -> 0.0056406992 | AJ24: =R24*D24 -> -0.0028203496 | AK24: =D24*S24 -> 0.0028203496 | AL24: =T24*D24 -> 0.0014101748 | AM24: =V24*D24 -> 0.0014101748 | AN24: =D24*W24 -> 0 | AO24: =$D24*X24 -> 0 | AP24: =$D24*Y24 -> 0
A25: tyrosine | B25: 181.19 | C25: 2 | D25: =(C25/100)*24*(1/B25) -> 0.0026491528 | E25: =((F25*B25*(10^(-6)))/1)*100 -> 2.373589 | F25: 131 | K25: 1 | L25: 2 | Q25: 1 | R25: -1 | S25: 1 | T25: 1 | AA25: =I25*D25 -> 0 | AB25: =J25*D25 -> 0 | AC25: =K25*D25 -> 0.0026491528 | AD25: =L25*D25 -> 0.0052983056 | AE25: =M25*D25 -> 0 | AF25: =N25*D25 -> 0 | AG25: =O25*D25 -> 0 | AH25: =P25*D25 -> 0 | AI25: =Q25*D25 -> 0.0026491528 | AJ25: =R25*D25 -> -0.0026491528 | AK25: =D25*S25 -> 0.0026491528 | AL25: =T25*D25 -> 0.0026491528 | AM25: =V25*D25 -> 0 | AN25: =D25*W25 -> 0 | AO25: =$D25*X25 -> 0 | AP25: =$D25*Y25 -> 0
A26: valine | B26: 117.151 | C26: 3.9 | D26: =(C26/100)*24*(1/B26) -> 0.0079896885 | E26: =((F26*B26*(10^(-6)))/1)*100 -> 4.7094702 | F26: 402 | M26: 2 | S26: 1 | T26: 1 | AA26: =I26*D26 -> 0 | AB26: =J26*D26 -> 0 | AC26: =K26*D26 -> 0 | AD26: =L26*D26 -> 0 | AE26: =M26*D26 -> 0.015979377 | AF26: =N26*D26 -> 0 | AG26: =O26*D26 -> 0 | AH26: =P26*D26 -> 0 | AI26: =Q26*D26 -> 0 | AJ26: =R26*D26 -> 0 | AK26: =D26*S26 -> 0.0079896885 | AL26: =T26*D26 -> 0.0079896885 | AM26: =V26*D26 -> 0 | AN26: =D26*W26 -> 0 | AO26: =$D26*X26 -> 0 | AP26: =$D26*Y26 -> 0
A27: percent sum | B27: protein estimated at 55.1.% | C27: =SUM(C7:C26) -> 55.1 | E27: =SUM(E7:E26) -> 64.182385 | F27: =F7+F8+F9+F10+F11+F12+F13+F14+F15+F16+F17+F18+F19+F20+F21+F22+F23+F24+F25+F26 -> 5081
Z28: sumProt: | AA28: =AA7+AA8+AA9+AA10+AA11+AA12+AA13+AA14+AA15+AA16+AA17+AA18+AA19+AA20+AA21+AA22+AA23+AA24+AA25+AA26 -> 0 | AB28: =AB7+AB8+AB9+AB10+AB11+AB12+AB13+AB14+AB15+AB16+AB17+AB18+AB19+AB20+AB21+AB22+AB23+AB24+AB25+AB26 -> 0.003575821 | AC28: =AC7+AC8+AC9+AC10+AC11+AC12+AC13+AC14+AC15+AC16+AC17+AC18+AC19+AC20+AC21+AC22+AC23+AC24+AC25+AC26 -> 0.0082726577 | AD28: =AD7+AD8+AD9+AD10+AD11+AD12+AD13+AD14+AD15+AD16+AD17+AD18+AD19+AD20+AD21+AD22+AD23+AD24+AD25+AD26 -> 0.031136596 | AE28: =AE7+AE8+AE9+AE10+AE11+AE12+AE13+AE14+AE15+AE16+AE17+AE18+AE19+AE20+AE21+AE22+AE23+AE24+AE25+AE26 -> 0.057811686 | AF28: =AF7+AF8+AF9+AF10+AF11+AF12+AF13+AF14+AF15+AF16+AF17+AF18+AF19+AF20+AF21+AF22+AF23+AF24+AF25+AF26 -> 0.009880308 | AG28: =AG7+AG8+AG9+AG10+AG11+AG12+AG13+AG14+AG15+AG16+AG17+AG18+AG19+AG20+AG21+AG22+AG23+AG24+AG25+AG26 -> 0.021531454 | AH28: =AH7+AH8+AH9+AH10+AH11+AH12+AH13+AH14+AH15+AH16+AH17+AH18+AH19+AH20+AH21+AH22+AH23+AH24+AH25+AH26 -> 0.026020312 | ... AN28: =AN7+AN8+AN9+AN10+AN11+AN12+AN13+AN14+AN15+AN16+AN17+AN18+AN19+AN20+AN21+AN22+AN23+AN24+AN25+AN26 -> -0.010320779 | AO28: =SUM(AO7:AO26) -> 0 | AP28: =SUM(AP7:AP26) -> 0
A29: RNA
A31: ATP | B31: 503.15 | D31: =($C$35/100)*24*(1/$B$35)*G31 -> 0.0023295872 | E31: =((F31*B31*(10^(-6)))/1)*100 -> 8.301975 | F31: 165 | G31: =339/1410 -> 0.24042553 | J31: 1 | L31: 1 | Q31: 7 | R31: -3 | S31: 0 | T31: 1 | V31: 4 | W31: 1 | AA31: =D31*I31 -> 0 | AB31: =D31*J31 -> 0.0023295872 | AC31: =D31*K31 -> 0 | AD31: =D31*L31 -> 0.0023295872 | AE31: =D31*M31 -> 0 | AF31: =D31*N31 -> 0 | AG31: =D31*O31 -> 0 | AH31: =D31*P31 -> 0 | AI31: =D31*Q31 -> 0.01630711 | AJ31: =D31*R31 -> -0.0069887616 | AK31: =D31*S31 -> 0 | AL31: =D31*T31 -> 0.0023295872 | AM31: =D31*V31 -> 0.0093183488 | AN31: =D31*W31 -> 0.0023295872 | AO31: =$D31*X31 -> 0 | AP31: =$D31*Y31 -> 0
A32: GTP | B32: 519.15 | D32: =($C$35/100)*24*(1/$B$35)*G32 -> 0.002350203 | E32: =((F32*B32*(10^(-6)))/1)*100 -> 10.538745 | F32: 203 | G32: =342/1410 -> 0.24255319 | J32: 1 | L32: 1 | Q32: 8 | R32: -3 | S32: 0 | V32: 5 | W32: 1 | AA32: =D32*I32 -> 0 | AB32: =D32*J32 -> 0.002350203 | AC32: =D32*K32 -> 0 | AD32: =D32*L32 -> 0.002350203 | AE32: =D32*M32 -> 0 | AF32: =D32*N32 -> 0 | AG32: =D32*O32 -> 0 | AH32: =D32*P32 -> 0 | AI32: =D32*Q32 -> 0.018801624 | AJ32: =D32*R32 -> -0.007050609 | AK32: =D32*S32 -> 0 | AL32: =D32*T32 -> 0 | AM32: =D32*V32 -> 0.011751015 | AN32: =D32*W32 -> 0.002350203 | AO32: =$D32*X32 -> 0 | AP32: =$D32*Y32 -> 0
A33: CTP | B33: 479.13 | D33: =($C$35/100)*24*(1/$B$35)*G33 -> 0.003133604 | E33: =((F33*B33*(10^(-6)))/1)*100 -> 6.037038 | F33: 126 | G33: =456/1410 -> 0.32340426 | J33: 1 | P33: 1 | Q33: 7 | R33: 0 | S33: 0 | T33: 1 | V33: 2 | AA33: =D33*I33 -> 0 | AB33: =D33*J33 -> 0.003133604 | AC33: =D33*K33 -> 0 | AD33: =D33*L33 -> 0 | AE33: =D33*M33 -> 0 | AF33: =D33*N33 -> 0 | AG33: =D33*O33 -> 0 | AH33: =D33*P33 -> 0.003133604 | AI33: =D33*Q33 -> 0.021935228 | AJ33: =D33*R33 -> 0 | AK33: =D33*S33 -> 0 | AL33: =D33*T33 -> 0.003133604 | AM33: =D33*V33 -> 0.006267208 | AN33: =D33*W33 -> 0 | AO33: =$D33*X33 -> 0 | AP33: =$D33*Y33 -> 0
A34: UTP | B34: 480.11 | D34: =($C$35/100)*24*(1/$B$35)*G34 -> 0.0018760392 | E34: =((F34*B34*(10^(-6)))/1)*100 -> 6.529496 | F34: 136 | G34: =273/1410 -> 0.19361702 | J34: 1 | P34: 1 | Q34: 6 | S34: 0 | T34: 1 | V34: 1 | AA34: =D34*I34 -> 0 | AB34: =D34*J34 -> 0.0018760392 | AC34: =D34*K34 -> 0 | AD34: =D34*L34 -> 0 | AE34: =D34*M34 -> 0 | AF34: =D34*N34 -> 0 | AG34: =D34*O34 -> 0 | AH34: =D34*P34 -> 0.0018760392 | AI34: =D34*Q34 -> 0.011256235 | AJ34: =D34*R34 -> 0 | AK34: =D34*S34 -> 0 | AL34: =D34*T34 -> 0.0018760392 | AM34: =D34*V34 -> 0.0018760392 | AN34: =D34*W34 -> 0 | AO34: =$D34*X34 -> 0 | AP34: =$D34*Y34 -> 0
A35: average molecular weight | B35: =SUM(B31:B34)/4 -> 495.385 | C35: 20 | D35: sum | F35: =F31+F32+F33+F34 -> 630 | G35: =SUM(G31:G34) -> 1
A36: DNA | Z36: sumRNA: | AA36: =AA31+AA32+AA33+AA34 -> 0 | AB36: =AB31+AB32+AB33+AB34 -> 0.0096894335 | AC36: =AC31+AC32+AC33+AC34 -> 0 | AD36: =AD31+AD32+AD33+AD34 -> 0.0046797902 | AE36: =AE31+AE32+AE33+AE34 -> 0 | AF36: =AF31+AF32+AF33+AF34 -> 0 | AG36: =AG31+AG32+AG33+AG34 -> 0 | AH36: =AH31+AH32+AH33+AH34 -> 0.0050096433 | ... AN36: =AN31+AN32+AN33+AN34 -> 0.0046797902 | AO36: =SUM(AO31:AO34) -> 0 | AP36: =SUM(AP31:AP34) -> 0
A38: dATP | B38: 487.15 | D38: =($C$42/100)*24*(1/$B$42)*G38 -> 0.00025526178 | E38: =((G38*B38*(10^(-6)))/1)*100 -> 0.008340008 | F38: 24.7 | G38: =0.5*(100-65.76)/100 -> 0.1712 | J38: 1 | L38: 1 | Q38: 7 | R38: -3 | S38: 1 | T38: 1 | V38: 4 | W38: 1 | AA38: =$D38*I38 -> 0 | AB38: =$D38*J38 -> 0.00025526178 | AC38: =$D38*K38 -> 0 | AD38: =$D38*L38 -> 0.00025526178 | AE38: =$D38*M38 -> 0 | AF38: =$D38*N38 -> 0 | AG38: =$D38*O38 -> 0 | AH38: =$D38*P38 -> 0 | ... AL38: =$D38*T38 -> 0.00025526178 | AM38: =$D38*V38 -> 0.0010210471 | AN38: =$D38*W38 -> 0.00025526178 | AO38: =$D38*X38 -> 0 | AP38: =$D38*Y38 -> 0
A39: dGTP | B39: 503.15 | D39: =($C$42/100)*24*(1/$B$42)*G39 -> 0.00049024576 | E39: =((G39*B39*(10^(-6)))/1)*100 -> 0.016543572 | F39: 25.4 | G39: =65.76/2/100 -> 0.3288 | J39: 1 | L39: 1 | Q39: 7 | R39: -3 | S39: 1 | V39: 5 | W39: 1 | AA39: =D39*I39 -> 0 | AB39: =$D39*J39 -> 0.00049024576 | AC39: =$D39*K39 -> 0 | AD39: =$D39*L39 -> 0.00049024576 | AE39: =$D39*M39 -> 0 | AF39: =$D39*N39 -> 0 | AG39: =$D39*O39 -> 0 | AH39: =$D39*P39 -> 0 | AI39: =$D39*Q39 -> 0.0034317203 | ... AL39: =$D39*T39 -> 0 | AM39: =$D39*V39 -> 0.0024512288 | AN39: =$D39*W39 -> 0.00049024576 | AO39: =$D39*X39 -> 0 | AP39: =$D39*Y39 -> 0
A40: dCTP | B40: 463.13 | D40: =($C$42/100)*24*(1/$B$42)*G40 -> 0.00049024576 | E40: =((G40*B40*(10^(-6)))/1)*100 -> 0.015227714 | F40: 25.4 | G40: =65.76/2/100 -> 0.3288 | J40: 1 | P40: 1 | Q40: 7 | R40: 0 | S40: 1 | T40: 1 | V40: 2 | AA40: =D40*I40 -> 0 | AB40: =$D40*J40 -> 0.00049024576 | AC40: =$D40*K40 -> 0 | AD40: =$D40*L40 -> 0 | AE40: =$D40*M40 -> 0 | AF40: =$D40*N40 -> 0 | AG40: =$D40*O40 -> 0 | AH40: =$D40*P40 -> 0.00049024576 | AI40: =$D40*Q40 -> 0.0034317203 | ... AL40: =$D40*T40 -> 0.00049024576 | AM40: =$D40*V40 -> 0.00098049152 | AN40: =$D40*W40 -> 0 | AO40: =$D40*X40 -> 0 | AP40: =$D40*Y40 -> 0
A41: dTTP | B41: 478.14 | D41: =($C$42/100)*24*(1/$B$42)*G41 -> 0.00025526178 | E41: =((G41*B41*(10^(-6)))/1)*100 -> 0.0081857568 | F41: 24.7 | G41: =0.5*(100-65.76)/100 -> 0.1712 | J41: 1 | P41: 1 | Q41: 9.5 | S41: 2 | T41: 1 | V41: 1 | AA41: =D41*I41 -> 0 | AB41: =$D41*J41 -> 0.00025526178 | AC41: =$D41*K41 -> 0 | AD41: =$D41*L41 -> 0 | AE41: =$D41*M41 -> 0 | AF41: =$D41*N41 -> 0 | AG41: =$D41*O41 -> 0 | AH41: =$D41*P41 -> 0.00025526178 | AI41: =$D41*Q41 -> 0.0024249869 | ... AL41: =$D41*T41 -> 0.00025526178 | AM41: =$D41*V41 -> 0.00025526178 | AN41: =$D41*W41 -> 0 | AO41: =$D41*X41 -> 0 | AP41: =$D41*Y41 -> 0
A42: average molecular weight | B42: =SUM(B38:B41)/4 -> 482.8925 | C42: 3 | D42: sum | F42: =F38+F39+F40+F41 -> 100.2 | G42: =G38+G39+G40+G41 -> 1
A43: Lipid | Z43: sumDNA: | AA43: =AA38+AA39+AA40+AA41 -> 0 | AB43: =AB38+AB39+AB40+AB41 -> 0.0014910151 | AC43: =AC38+AC39+AC40+AC41 -> 0 | AD43: =AD38+AD39+AD40+AD41 -> 0.00074550754 | AE43: =AE38+AE39+AE40+AE41 -> 0 | AF43: =AF38+AF39+AF40+AF41 -> 0 | AG43: =AG38+AG39+AG40+AG41 -> 0 | AH43: =AH38+AH39+AH40+AH41 -> 0.00074550754 | ... AN43: =AN38+AN39+AN40+AN41 -> 0.00074550754 | AO43: =SUM(AO38:AO41) -> 0 | AP43: =SUM(AP38:AP41) -> 0
A45: Glycerol phosphate | B45: 170.06 | D45: =(E45/$E$48)*($C$48/100)*24*(1/B45) -> 0.0027698468 | E45: =((F45*B45*(10^(-6)))/1)*100 -> 2.193774 | F45: 129 | L45: 1 | Q45: 0 | R45: 0 | S45: 1 | AA45: =$D45*I45 -> 0 | AB45: =$D45*J45 -> 0 | AC45: =$D45*K45 -> 0 | AD45: =$D45*L45 -> 0.0027698468 | AE45: =$D45*M45 -> 0 | AF45: =$D45*N45 -> 0 | AG45: =$D45*O45 -> 0 | AH45: =$D45*P45 -> 0 | ... AL45: =$D45*T45 -> 0 | AM45: =$D45*V45 -> 0 | AN45: =$D45*W45 -> 0 | AO45: =$D45*X45 -> 0 | AP45: =$D45*Y45 -> 0
...

Sheet type II biomass calculations 
C3: ORIGINAL
C4: Compound name biomass sheet | D4: compound name in model | E4: mol compound in biomass term | F4: chemical formula | G4: charge | H4: C | I4: H | J4: N | K4: O | L4: P | M4: S | N4: E | P4: NO3- degree of reduction | Q4: NH4+ degree of reduction | R4: N2 degree of reduction
A5: left side of equation | C5: ='type II biomass composition'!$AA$6 -> glc-6-p | D5: D-glucopyranose_6-phosphate | E5: 0.33525018 | F5: C6H11O9P | G5: -2 | H5: 6 | I5: 11 | K5: 9 | L5: 1 | N5: =(4*H5)+(I5)+(-3*J5)+(-2*K5)+(5*L5)+(-2*M5)+(-1*G5) -> 24 | P5: =((4*(H5))+(I5)+(5*J5)+(-2*K5)+(5*L5)+(6*M5)+(-G5))/H5 -> 4 | Q5: =((4*(H5))+(I5)+(-3*J5)+(-2*K5)+(5*L5)+(6*M5)+(-G5))/H5 -> 4 | R5: =((4*(H5))+(I5)+(0*J5)+(-2*K5)+(5*L5)+(6*M5)+(-G5))/H5 -> 4
C6: ='type II biomass composition'!$AB$6 -> rib-5-p | D6: D-ribose_5-phosphate | E6: 2.7630039 | F6: C5H9O8P | G6: -2 | H6: 5 | I6: 9 | K6: 8 | L6: 1 | N6: =(4*H6)+(I6)+(-3*J6)+(-2*K6)+(5*L6)+(-2*M6)+(-1*G6) -> 20 | P6: =((4*(H6))+(I6)+(5*J6)+(-2*K6)+(5*L6)+(6*M6)+(-G6))/H6 -> 4 | Q6: =((4*(H6))+(I6)+(-3*J6)+(-2*K6)+(5*L6)+(6*M6)+(-G6))/H6 -> 4 | R6: =((4*(H6))+(I6)+(0*J6)+(-2*K6)+(5*L6)+(6*M6)+(-G6))/H6 -> 4
C7: ='type II biomass composition'!$AC$6 -> ery-4-p | D7: D-erythrose_4-phosphate | E7: 1.5116668 | F7: C4H7O7P | G7: -2 | H7: 4 | I7: 7 | K7: 7 | L7: 1 | N7: =(4*H7)+(I7)+(-3*J7)+(-2*K7)+(5*L7)+(-2*M7)+(-1*G7) -> 16 | P7: =((4*(H7))+(I7)+(5*J7)+(-2*K7)+(5*L7)+(6*M7)+(-G7))/H7 -> 4 | Q7: =((4*(H7))+(I7)+(-3*J7)+(-2*K7)+(5*L7)+(6*M7)+(-G7))/H7 -> 4 | R7: =((4*(H7))+(I7)+(0*J7)+(-2*K7)+(5*L7)+(6*M7)+(-G7))/H7 -> 4
C8: ='type II biomass composition'!$AD$6 -> pep | D8: phosphoenolpyruvate | E8: 8.1917332 | F8: C3H2O6P | G8: -3 | H8: 3 | I8: 2 | K8: 6 | L8: 1 | N8: 10 | P8: =((4*(H8))+(I8)+(5*J8)+(-2*K8)+(5*L8)+(6*M8)+(-G8))/H8 -> 3.3333333 | Q8: =((4*(H8))+(I8)+(-3*J8)+(-2*K8)+(5*L8)+(6*M8)+(-G8))/H8 -> 3.3333333 | R8: =((4*(H8))+(I8)+(0*J8)+(-2*K8)+(5*L8)+(6*M8)+(-G8))/H8 -> 3.3333333
C9: ='type II biomass composition'!$AE$6 -> pyr | D9: pyruvate | E9: 10.78357 | F9: C3H3O3 | G9: -1 | H9: 3 | I9: 3 | K9: 3 | N9: =(4*H9)+(I9)+(-3*J9)+(-2*K9)+(5*L9)+(-2*M9)+(-1*G9) -> 10 | P9: =((4*(H9))+(I9)+(5*J9)+(-2*K9)+(5*L9)+(6*M9)+(-G9))/H9 -> 3.3333333 | Q9: =((4*(H9))+(I9)+(-3*J9)+(-2*K9)+(5*L9)+(6*M9)+(-G9))/H9 -> 3.3333333 | R9: =((4*(H9))+(I9)+(0*J9)+(-2*K9)+(5*L9)+(6*M9)+(-G9))/H9 -> 3.3333333
C10: ='type II biomass composition'!$AF$6 -> ace-coa | D10: acetyl-CoA | E10: 10.982178 | F10: C23H34N7O17P3S | G10: -4 | H10: 23 | I10: 34 | J10: 7 | K10: 17 | L10: 3 | M10: 1 | N10: 88 | P10: =((4*(H10))+(I10)+(5*J10)+(-2*K10)+(5*L10)+(6*M10)+(-G10))/H10 -> 6.6086957 | Q10: =((4*(H10))+(I10)+(-3*J10)+(-2*K10)+(5*L10)+(6*M10)+(-G10))/H10 -> 4.173913 | R10: =((4*(H10))+(I10)+(0*J10)+(-2*K10)+(5*L10)+(6*M10)+(-G10))/H10 -> 5.0869565
C11: ='type II biomass composition'!$AG$6 -> akg | D11: 2-oxoglutarate | E11: 4.0076572 | F11: C5H4O5 | G11: -2 | H11: 5 | I11: 4 | K11: 5 | N11: =(4*H11)+(I11)+(-3*J11)+(-2*K11)+(5*L11)+(-2*M11)+(-1*G11) -> 16 | P11: =((4*(H11))+(I11)+(5*J11)+(-2*K11)+(5*L11)+(6*M11)+(-G11))/H11 -> 3.2 | Q11: =((4*(H11))+(I11)+(-3*J11)+(-2*K11)+(5*L11)+(6*M11)+(-G11))/H11 -> 3.2 | R11: =((4*(H11))+(I11)+(0*J11)+(-2*K11)+(5*L11)+(6*M11)+(-G11))/H11 -> 3.2
C12: ='type II biomass composition'!$AH$6 -> oxalo | D12: oxaloacetate | E12: 5.8795501 | F12: C4H2O5 | G12: -2 | H12: 4 | I12: 2 | K12: 5 | N12: 10 | P12: =((4*(H12))+(I12)+(5*J12)+(-2*K12)+(5*L12)+(6*M12)+(-G12))/H12 -> 2.5 | Q12: =((4*(H12))+(I12)+(-3*J12)+(-2*K12)+(5*L12)+(6*M12)+(-G12))/H12 -> 2.5 | R12: =((4*(H12))+(I12)+(0*J12)+(-2*K12)+(5*L12)+(6*M12)+(-G12))/H12 -> 2.5
C13: ='type II biomass composition'!$AI$6 -> atp | D13: ATP | E13: 45.955146 | F13: C10H12N5O13P3 | G13: -4 | H13: 10 | I13: 12 | J13: 5 | K13: 13 | L13: 3 | N13: =(4*H13)+(I13)+(-3*J13)+(-2*K13)+(5*L13)+(-2*M13)+(-1*G13) -> 30 | P13: =((4*(H13))+(I13)+(5*J13)+(-2*K13)+(5*L13)+(6*M13)+(-G13))/H13 -> 7 | Q13: =((4*(H13))+(I13)+(-3*J13)+(-2*K13)+(5*L13)+(6*M13)+(-G13))/H13 -> 3 | R13: =((4*(H13))+(I13)+(0*J13)+(-2*K13)+(5*L13)+(6*M13)+(-G13))/H13 -> 4.5
C14: ='type II biomass composition'!$AK$6 -> nadph | D14: NADPH | E14: -12.064074 | F14: C21H26N7O17P3 | G14: -4 | H14: 21 | I14: 26 | J14: 7 | K14: 17 | L14: 3 | N14: =(4*H14)+(I14)+(-3*J14)+(-2*K14)+(5*L14)+(-2*M14)+(-1*G14) -> 74 | P14: =((4*(H14))+(I14)+(5*J14)+(-2*K14)+(5*L14)+(6*M14)+(-G14))/H14 -> 6.1904762 | Q14: =((4*(H14))+(I14)+(-3*J14)+(-2*K14)+(5*L14)+(6*M14)+(-G14))/H14 -> 3.5238095 | R14: =((4*(H14))+(I14)+(0*J14)+(-2*K14)+(5*L14)+(6*M14)+(-G14))/H14 -> 4.5238095
C15: ='type II biomass composition'!$AL$6 -> N_GLU | D15: N_GLU | E15: 35.716491 | F15: NH4+ | G15: 1 | I15: 4 | J15: 1 | N15: =(4*H15)+(I15)+(-3*J15)+(-2*K15)+(5*L15)+(-2*M15)+(-1*G15) -> 0 | P15: =((4*(H15))+(I15)+(5*J15)+(-2*K15)+(5*L15)+(6*M15)+(-G15))/H15 -> #DIV/0! | Q15: =((4*(H15))+(I15)+(-3*J15)+(-2*K15)+(5*L15)+(6*M15)+(-G15))/H15 -> #DIV/0! | R15: =((4*(H15))+(I15)+(0*J15)+(-2*K15)+(5*L15)+(6*M15)+(-G15))/H15 -> #DIV/0!
C16: ='type II biomass composition'!$AM$6 -> N_GLN | D16: N_GLN | E16: 24.930427 | F16: NH4+ | G16: 1 | I16: 4 | J16: 1 | N16: =(4*H16)+(I16)+(-3*J16)+(-2*K16)+(5*L16)+(-2*M16)+(-1*G16) -> 0 | P16: =((4*(H16))+(I16)+(5*J16)+(-2*K16)+(5*L16)+(6*M16)+(-G16))/H16 -> #DIV/0! | Q16: =((4*(H16))+(I16)+(-3*J16)+(-2*K16)+(5*L16)+(6*M16)+(-G16))/H16 -> #DIV/0! | R16: =((4*(H16))+(I16)+(0*J16)+(-2*K16)+(5*L16)+(6*M16)+(-G16))/H16 -> #DIV/0!
C17: ='type II biomass composition'!$AO$6 -> polyhydroxybutyrate | D17: polyhydroxybutyrate_produced | E17: 0.58318243 | F17: C4H7O3 | G17: -1 | H17: 4 | I17: 7 | K17: 3 | N17: 18 | P17: =((4*(H17))+(I17)+(5*J17)+(-2*K17)+(5*L17)+(6*M17)+(-G17))/H17 -> 4.5 | Q17: =((4*(H17))+(I17)+(-3*J17)+(-2*K17)+(5*L17)+(6*M17)+(-G17))/H17 -> 4.5 | R17: =((4*(H17))+(I17)+(0*J17)+(-2*K17)+(5*L17)+(6*M17)+(-G17))/H17 -> 4.5
C18: ='type II biomass composition'!$AP$6 -> L-ornithine | D18: L-ornithine | E18: 0.13172732 | F18: C5H13N2O2 | G18: 1 | H18: 5 | I18: 13 | J18: 2 | K18: 2 | N18: =(4*H18)+(I18)+(-3*J18)+(-2*K18)+(5*L18)+(-2*M18)+(-1*G18) -> 22 | P18: =((4*(H18))+(I18)+(5*J18)+(-2*K18)+(5*L18)+(6*M18)+(-G18))/H18 -> 7.6 | Q18: =((4*(H18))+(I18)+(-3*J18)+(-2*K18)+(5*L18)+(6*M18)+(-G18))/H18 -> 4.4 | R18: =((4*(H18))+(I18)+(0*J18)+(-2*K18)+(5*L18)+(6*M18)+(-G18))/H18 -> 5.6
C19: polymerization ATP | D19: polymerization ATP | E19: 100 | F19: C10H12N5O13P3 | G19: -4 | H19: 10 | I19: 12 | J19: 5 | K19: 13 | L19: 3 | N19: =(4*H19)+(I19)+(-3*J19)+(-2*K19)+(5*L19)+(-2*M19)+(-1*G19) -> 30 | P19: =((4*(H19))+(I19)+(5*J19)+(-2*K19)+(5*L19)+(6*M19)+(-G19))/H19 -> 7 | Q19: =((4*(H19))+(I19)+(-3*J19)+(-2*K19)+(5*L19)+(6*M19)+(-G19))/H19 -> 3 | R19: =((4*(H19))+(I19)+(0*J19)+(-2*K19)+(5*L19)+(6*M19)+(-G19))/H19 -> 4.5
C20: NAD+ | D20: NAD+ | E20: =-(E23) -> -12.064 | F20: C21H26N7O14P2 | G20: -1 | H20: 21 | I20: 26 | J20: 7 | K20: 14 | L20: 2 | N20: =(4*H20)+(I20)+(-3*J20)+(-2*K20)+(5*L20)+(-2*M20)+(-1*G20) -> 72 | P20: =((4*(H20))+(I20)+(5*J20)+(-2*K20)+(5*L20)+(6*M20)+(-G20))/H20 -> 6.0952381 | Q20: =((4*(H20))+(I20)+(-3*J20)+(-2*K20)+(5*L20)+(6*M20)+(-G20))/H20 -> 3.4285714 | R20: =((4*(H20))+(I20)+(0*J20)+(-2*K20)+(5*L20)+(6*M20)+(-G20))/H20 -> 4.4285714
C21: H2O | D21: H2O | E21: =E19+E13 -> 145.95515 | F21: H2O | G21: 0 | I21: 2 | K21: 1 | N21: =(4*H21)+(I21)+(-3*J21)+(-2*K21)+(5*L21)+(-2*M21)+(-1*G21) -> 0 | Q21: =((4*(H21))+(I21)+(-3*J21)+(-2*K21)+(5*L21)+(6*M21)+(-G21))/H21 -> #DIV/0!
Q22: =((4*(H22))+(I22)+(-3*J22)+(-2*K22)+(5*L22)+(6*M22)+(-G22))/H22 -> #DIV/0!
A23: right side of equation | C23: ='type II biomass composition'!$AJ$6 -> nadh | D23: NADH | E23: 12.064 | F23: C21H27N7O14P2 | G23: -2 | H23: 21 | I23: 27 | J23: 7 | K23: 14 | L23: 2 | N23: =(4*H23)+(I23)+(-3*J23)+(-2*K23)+(5*L23)+(-2*M23)+(-1*G23) -> 74 | P23: =((4*(H23))+(I23)+(5*J23)+(-2*K23)+(5*L23)+(6*M23)+(-G23))/H23 -> 6.1904762 | Q23: =((4*(H23))+(I23)+(-3*J23)+(-2*K23)+(5*L23)+(6*M23)+(-G23))/H23 -> 3.5238095 | R23: =((4*(H23))+(I23)+(0*J23)+(-2*K23)+(5*L23)+(6*M23)+(-G23))/H23 -> 4.5238095
C24: ='type II biomass composition'!$AN$6 -> co2 | D24: CO2 | E24: 0.89455375 | F24: CO2 | G24: 0 | H24: 1 | K24: 2 | N24: =(4*H24)+(I24)+(-3*J24)+(-2*K24)+(5*L24)+(-2*M24)+(-1*G24) -> 0 | P24: =((4*(H24))+(I24)+(5*J24)+(-2*K24)+(5*L24)+(6*M24)+(-G24))/H24 -> 0 | Q24: =((4*(H24))+(I24)+(-3*J24)+(-2*K24)+(5*L24)+(6*M24)+(-G24))/H24 -> 0 | R24: =((4*(H24))+(I24)+(0*J24)+(-2*K24)+(5*L24)+(6*M24)+(-G24))/H24 -> 0
C25: phosphate | D25: phosphate | E25: =(E13+E19) -> 145.95515 | F25: HO4P | G25: -2 | I25: 1 | K25: 4 | L25: 1 | N25: =(4*H25)+(I25)+(-3*J25)+(-2*K25)+(5*L25)+(-2*M25)+(-1*G25) -> 0 | P25: =((4*(H25))+(I25)+(5*J25)+(-2*K25)+(5*L25)+(6*M25)+(-G25))/H25 -> #DIV/0! | Q25: =((4*(H25))+(I25)+(-3*J25)+(-2*K25)+(5*L25)+(6*M25)+(-G25))/H25 -> #DIV/0! | R25: =((4*(H25))+(I25)+(0*J25)+(-2*K25)+(5*L25)+(6*M25)+(-G25))/H25 -> #DIV/0!
C26: ADP | D26: ADP | E26: =(E13+E19) -> 145.95515 | F26: C10H12N5O10P2 | G26: -3 | H26: 10 | I26: 12 | J26: 5 | K26: 10 | L26: 2 | N26: =(4*H26)+(I26)+(-3*J26)+(-2*K26)+(5*L26)+(-2*M26)+(-1*G26) -> 30 | P26: =((4*(H26))+(I26)+(5*J26)+(-2*K26)+(5*L26)+(6*M26)+(-G26))/H26 -> 7 | Q26: =((4*(H26))+(I26)+(-3*J26)+(-2*K26)+(5*L26)+(6*M26)+(-G26))/H26 -> 3 | R26: =((4*(H26))+(I26)+(0*J26)+(-2*K26)+(5*L26)+(6*M26)+(-G26))/H26 -> 4.5
C27: COA | D27: coenzyme_A | E27: =(E10) -> 10.982178 | F27: C21H32N7O16P3S | G27: -4 | H27: 21 | I27: 32 | J27: 7 | K27: 16 | L27: 3 | M27: 1 | N27: 80 | P27: =((4*(H27))+(I27)+(5*J27)+(-2*K27)+(5*L27)+(6*M27)+(-G27))/H27 -> 6.8571429 | Q27: =((4*(H27))+(I27)+(-3*J27)+(-2*K27)+(5*L27)+(6*M27)+(-G27))/H27 -> 4.1904762 | R27: =((4*(H27))+(I27)+(0*J27)+(-2*K27)+(5*L27)+(6*M27)+(-G27))/H27 -> 5.1904762
C28: H+ | D28: H+ | E28: =(E13+E21) -> 191.91029 | F28: H | G28: 1 | I28: 1 | N28: =(4*H28)+(I28)+(-3*J28)+(-2*K28)+(5*L28)+(-2*M28)+(-1*G28) -> 0 | P28: 0 | Q28: 0 | R28: 0
C29: NADP+ | D29: NADP+ | E29: =-(E14) -> 12.064074 | F29: C21H25N7O17P3 | G29: -3 | H29: 21 | I29: 25 | J29: 7 | K29: 17 | L29: 3 | N29: =(4*H29)+(I29)+(-3*J29)+(-2*K29)+(5*L29)+(-2*M29)+(-1*G29) -> 72 | P29: =((4*(H29))+(I29)+(5*J29)+(-2*K29)+(5*L29)+(6*M29)+(-G29))/H29 -> 6.0952381 | Q29: =((4*(H29))+(I29)+(-3*J29)+(-2*K29)+(5*L29)+(6*M29)+(-G29))/H29 -> 3.4285714 | R29: =((4*(H29))+(I29)+(0*J29)+(-2*K29)+(5*L29)+(6*M29)+(-G29))/H29 -> 4.4285714
A36: *B35 is a blank space | C36: biomass term no adjustments | D36: biomass | G36: =SUM(($E5*G5)+($E6*G6)+($E7*G7)+($E8*G8)+($E9*G9)+($E10*G10)+($E11*G11)+($E12*G12)+($E13*G13)+($E14*G14)+($E15*G15)+($E16*G16)+($E17*G17)+($E18*G18)+($E19*G19)+($E20*G20)+($E21*G21))+SUM(($E23*G23)+($E24*G24)+($E25*G25)+($E26*G26)+($E27*G27)+($E28*G28)+($E29*G29)) -> -1213.7009 | H36: =SUM(($E5*H5)+($E6*H6)+($E7*H7)+($E8*H8)+($E9*H9)+($E10*H10)+($E11*H11)+($E12*H12)+($E13*H13)+($E14*H14)+($E15*H15)+($E16*H16)+($E17*H17)+($E18*H18)+($E19*H19)+($E20*H20)+($E21*H21))+SUM(($E23*H23)+($E24*H24)+($E25*H25)+($E26*H26)+($E27*H27)+($E28*H28)+($E29*H29)) -> 3528.5603 | I36: =SUM(($E5*I5)+($E6*I6)+($E7*I7)+($E8*I8)+($E9*I9)+($E10*I10)+($E11*I11)+($E12*I12)+($E13*I13)+($E14*I14)+($E15*I15)+($E16*I16)+($E17*I17)+($E18*I18)+($E19*I19)+($E20*I20)+($E21*I21))+SUM(($E23*I23)+($E24*I24)+($E25*I25)+($E26*I26)+($E27*I27)+($E28*I28)+($E29*I29)) -> 5221.5657 | J36: =SUM(($E5*J5)+($E6*J6)+($E7*J7)+($E8*J8)+($E9*J9)+($E10*J10)+($E11*J11)+($E12*J12)+($E13*J13)+($E14*J14)+($E15*J15)+($E16*J16)+($E17*J17)+($E18*J18)+($E19*J19)+($E20*J20)+($E21*J21))+SUM(($E23*J23)+($E24*J24)+($E25*J25)+($E26*J26)+($E27*J27)+($E28*J28)+($E29*J29)) -> 1674.2123 | K36: =SUM(($E5*K5)+($E6*K6)+($E7*K7)+($E8*K8)+($E9*K9)+($E10*K10)+($E11*K11)+($E12*K12)+($E13*K13)+($E14*K14)+($E15*K15)+($E16*K16)+($E17*K17)+($E18*K18)+($E19*K19)+($E20*K20)+($E21*K21))+SUM(($E23*K23)+($E24*K24)+($E25*K25)+($E26*K26)+($E27*K27)+($E28*K28)+($E29*K29)) -> 4619.5982 | L36: =SUM(($E5*L5)+($E6*L6)+($E7*L7)+($E8*L8)+($E9*L9)+($E10*L10)+($E11*L11)+($E12*L12)+($E13*L13)+($E14*L14)+($E15*L15)+($E16*L16)+($E17*L17)+($E18*L18)+($E19*L19)+($E20*L20)+($E21*L21))+SUM(($E23*L23)+($E24*L24)+($E25*L25)+($E26*L26)+($E27*L27)+($E28*L28)+($E29*L29)) -> 954.4256 | M36: =SUM(($E5*M5)+($E6*M6)+($E7*M7)+($E8*M8)+($E9*M9)+($E10*M10)+($E11*M11)+($E12*M12)+($E13*M13)+($E14*M14)+($E15*M15)+($E16*M16)+($E17*M17)+($E18*M18)+($E19*M19)+($E20*M20)+($E21*M21))+SUM(($E23*M23)+($E24*M24)+($E25*M25)+($E26*M26)+($E27*M27)+($E28*M28)+($E29*M29)) -> 21.964356 | N36: =SUM(($E5*N5)+($E6*N6)+($E7*N7)+($E8*N8)+($E9*N9)+($E10*N10)+($E11*N11)+($E12*N12)+($E13*N13)+($E14*N14)+($E15*N15)+($E16*N16)+($E17*N17)+($E18*N18)+($E19*N19)+($E20*N20)+($E21*N21))+SUM(($E23*N23)+($E24*N24)+($E25*N25)+($E26*N26)+($E27*N27)+($E28*N28)+($E29*N29)) -> 11015.874 | P36: =((4*(H36))+(I36)+(5*J36)+(-2*K36)+(5*L36)+(6*M36)+(-G36))/H36 -> 6.9675123 | Q36: =((4*(H36))+(I36)+(-3*J36)+(-2*K36)+(5*L36)+(6*M36)+(-G36))/H36 -> 3.1717153 | R36: =((4*(H36))+(I36)+(0*J36)+(-2*K36)+(5*L36)+(6*M36)+(-G36))/H36 -> 4.5951392
A37: *I combined the two ATP terms into one metabolite with one coefficient. But could leave them separate, would just need an additional reaction converting ATP = ATP_polymerization | B37: + | C37: written out (automatic formula): | D37: =((E5&$B$36&(D5))&$B$36&$B$37&$B$36&(E6&$B$36&D6)&$B$36&$B$37&$B$36&(E7&$B$36&D7)&$B$36&$B$37&$B$36&(E8&$B$36&D8)&$B$36&$B$37&$B$36&(E9&$B$36&D9)&$B$36&$B$37&$B$36&(E10&$B$36&D10)&$B$36&$B$37&$B$36&(E11&$B$36&D11)&$B$36&$B$37&$B$36&(E12&$B$36&D12)&$B$36&$B$37&$B$36&((E13+E19)&$B$36&D13)&$B$36&$B$37&$B$36&(E14&$B$36&D14)&$B$36&$B$37&$B$36&(E15&$B$36&D15)&$B$36&$B$37&$B$36&(E16&$B$36&D16)&$B$36&$B$37&$B$36&(E17&$B$36&D17)&$B$36&$B$37&$B$36&(E18&$B$36&D18)&$B$36&$B$37&$B$36&(E20&$B$36&D20)&$B$36&$B$37&$B$36&(E21&$B$36&D21)&$B$36&$B$39&$B$36&(D36)&$B$36&$B$37&$B$36&(-E23&$B$36&D23)&$B$36&$B$37&$B$36&(-E24&$B$36&D24)&$B$36&$B$37&$B$36&(-E25&$B$36&D25)&$B$36&$B$37&$B$36&(-E26&$B$36&D26)&$B$36&$B$37&$B$36&(-E27&$B$36&D27)&$B$36&$B$37&$B$36&(-E28&$B$36&D28)&$B$36&$B$37&$B$36&(-E29&$B$36&D29)) -> 0.33525017878437 D-glucopyranose_6-phosphate + 2.76300389571188 D-ribose_5-phosphate + 1.51166682921877 D-erythrose_4-phosphate + 8.19173319968786 phosphoenolpyruvate + 10.7835700117804 pyruvate + 10.982178036237 acetyl-CoA + 4.00765717469613 2-oxoglutarate + 5.8795500917648 oxaloacetate + 145.955146001733 ATP + -12.0640743345486 NADPH + 35.7164912265533 N_GLU + 24.9304271663154 N_GLN + 0.583182425886587 polyhydroxybutyrate_produced + 0.131727321248543 L-ornithine + -12.064 NAD+ + 145.955146001733 H2O = biomass + -12.064 NADH + -0.894553752061566 CO2 + -145.955146001733 phosphate + -145.955146001733 ADP + -10.982178036237 coenzyme_A + -191.910292003466 H+ + -12.0640743345486 NADP+
B38: - | C38: as text (easier to read in text window): | D38: 0.33525017878437 D-glucopyranose_6-phosphate + 2.76300389571188 D-ribose_5-phosphate + 1.51166682921877 D-erythrose_4-phosphate + 8.19173319968786 phosphoenolpyruvate + 10.7835700117804 pyruvate + 10.982178036237 acetyl-CoA + 4.00765717469613 2-oxoglutarate + 5.8795500917648 oxaloacetate + 145.955146001733 ATP + 35.7164912265533 NADPH + 24.9304271663154 N_GLU + 9.84875191559127 N_GLN + 0.583182425886587 polyhydroxybutyrate_produced + 0.131727321248543 L-ornithine + 12.0640743345486 NAD+ + 145.955146001733 H2O = biomass + 12.0640743345486 NADH + 0.894553752061566 CO2 + 145.955146001733 phosphate + 145.955146001733 ADP + 10.982178036237 coenzyme_A + 191.910292003466 H+ + 35.7164912265533 NADP+
A39: *apostrophe in front of this one | B39: =
C41: DEGREE OF REDUCTION ADJUSTED SECTION, adjusting to DoR = 4.2
C42: Compound name biomass sheet | D42: compound name in model | E42: mol compound in biomass term | F42: chemical formula | G42: charge | H42: C | I42: H | J42: N | K42: O | L42: P | M42: S | N42: E | P42: NO3- degree of reduction | Q42: NH4+ degree of reduction | R42: N2 degree of reduction
A43: left side of equation | C43: ='[1]OB3b specific for type II'!$AA$23 -> glc-6-p | D43: D-glucopyranose_6-phosphate | E43: ='[1]OB3b specific for type II'!$AU$37 -> 0.33525018 | F43: C6H11O9P | G43: -2 | H43: 6 | I43: 11 | K43: 9 | L43: 1 | N43: =(4*H43)+(I43)+(-3*J43)+(-2*K43)+(5*L43)+(-2*M43)+(-1*G43) -> 24 | P43: =((4*(H43))+(I43)+(5*J43)+(-2*K43)+(5*L43)+(6*M43)+(-G43))/H43 -> 4 | Q43: =((4*(H43))+(I43)+(-3*J43)+(-2*K43)+(5*L43)+(6*M43)+(-G43))/H43 -> 4 | R43: =((4*(H43))+(I43)+(0*J43)+(-2*K43)+(5*L43)+(6*M43)+(-G43))/H43 -> 4
C44: ='[1]OB3b specific for type II'!$AB$23 -> rib-5-p | D44: D-ribose_5-phosphate | E44: ='[1]OB3b specific for type II'!$AV$37 -> 2.7630039 | F44: C5H9O8P | G44: -2 | H44: 5 | I44: 9 | K44: 8 | L44: 1 | N44: =(4*H44)+(I44)+(-3*J44)+(-2*K44)+(5*L44)+(-2*M44)+(-1*G44) -> 20 | P44: =((4*(H44))+(I44)+(5*J44)+(-2*K44)+(5*L44)+(6*M44)+(-G44))/H44 -> 4 | Q44: =((4*(H44))+(I44)+(-3*J44)+(-2*K44)+(5*L44)+(6*M44)+(-G44))/H44 -> 4 | R44: =((4*(H44))+(I44)+(0*J44)+(-2*K44)+(5*L44)+(6*M44)+(-G44))/H44 -> 4
C45: ='[1]OB3b specific for type II'!$AC$23 -> ery-4-p | D45: D-erythrose_4-phosphate | E45: ='[1]OB3b specific for type II'!$AW$37 -> 1.5116668 | F45: C4H7O7P | G45: -2 | H45: 4 | I45: 7 | K45: 7 | L45: 1 | N45: =(4*H45)+(I45)+(-3*J45)+(-2*K45)+(5*L45)+(-2*M45)+(-1*G45) -> 16 | P45: =((4*(H45))+(I45)+(5*J45)+(-2*K45)+(5*L45)+(6*M45)+(-G45))/H45 -> 4 | Q45: =((4*(H45))+(I45)+(-3*J45)+(-2*K45)+(5*L45)+(6*M45)+(-G45))/H45 -> 4 | R45: =((4*(H45))+(I45)+(0*J45)+(-2*K45)+(5*L45)+(6*M45)+(-G45))/H45 -> 4
C46: ='[1]OB3b specific for type II'!$AD$23 -> pep | D46: phosphoenolpyruvate | E46: ='[1]OB3b specific for type II'!$AX$37 -> 8.1917332 | F46: C3H2O6P | G46: -3 | H46: 3 | I46: 2 | K46: 6 | L46: 1 | N46: 10 | P46: =((4*(H46))+(I46)+(5*J46)+(-2*K46)+(5*L46)+(6*M46)+(-G46))/H46 -> 3.3333333 | Q46: =((4*(H46))+(I46)+(-3*J46)+(-2*K46)+(5*L46)+(6*M46)+(-G46))/H46 -> 3.3333333 | R46: =((4*(H46))+(I46)+(0*J46)+(-2*K46)+(5*L46)+(6*M46)+(-G46))/H46 -> 3.3333333
C47: ='[1]OB3b specific for type II'!$AE$23 -> pyr | D47: pyruvate | E47: ='[1]OB3b specific for type II'!$AY$37 -> 10.78357 | F47: C3H3O3 | G47: -1 | H47: 3 | I47: 3 | K47: 3 | N47: =(4*H47)+(I47)+(-3*J47)+(-2*K47)+(5*L47)+(-2*M47)+(-1*G47) -> 10 | P47: =((4*(H47))+(I47)+(5*J47)+(-2*K47)+(5*L47)+(6*M47)+(-G47))/H47 -> 3.3333333 | Q47: =((4*(H47))+(I47)+(-3*J47)+(-2*K47)+(5*L47)+(6*M47)+(-G47))/H47 -> 3.3333333 | R47: =((4*(H47))+(I47)+(0*J47)+(-2*K47)+(5*L47)+(6*M47)+(-G47))/H47 -> 3.3333333
C48: ='[1]OB3b specific for type II'!$AF$23 -> ace-coa | D48: acetyl-CoA | E48: ='[1]OB3b specific for type II'!$AZ$37 -> 10.982178 | F48: C23H34N7O17P3S | G48: -4 | H48: 23 | I48: 34 | J48: 7 | K48: 17 | L48: 3 | M48: 1 | N48: 88 | P48: =((4*(H48))+(I48)+(5*J48)+(-2*K48)+(5*L48)+(6*M48)+(-G48))/H48 -> 6.6086957 | Q48: =((4*(H48))+(I48)+(-3*J48)+(-2*K48)+(5*L48)+(6*M48)+(-G48))/H48 -> 4.173913 | R48: =((4*(H48))+(I48)+(0*J48)+(-2*K48)+(5*L48)+(6*M48)+(-G48))/H48 -> 5.0869565
C49: ='[1]OB3b specific for type II'!$AG$23 -> akg | D49: 2-oxoglutarate | E49: ='[1]OB3b specific for type II'!$BA$37 -> 4.0076572 | F49: C5H4O5 | G49: -2 | H49: 5 | I49: 4 | K49: 5 | N49: =(4*H49)+(I49)+(-3*J49)+(-2*K49)+(5*L49)+(-2*M49)+(-1*G49) -> 16 | P49: =((4*(H49))+(I49)+(5*J49)+(-2*K49)+(5*L49)+(6*M49)+(-G49))/H49 -> 3.2 | Q49: =((4*(H49))+(I49)+(-3*J49)+(-2*K49)+(5*L49)+(6*M49)+(-G49))/H49 -> 3.2 | R49: =((4*(H49))+(I49)+(0*J49)+(-2*K49)+(5*L49)+(6*M49)+(-G49))/H49 -> 3.2
...

Sheet biomass reaction variations
B2: alternative growth reactions considering different biomass degrees of reduction and growth associated maintenance energy
B3: first number in designator is biomass degree of reduction and second number is GAM in ATP per Cmol biomass
B5: Type II biomass
B6: biomass_typeII 4.2 1 ATP | C6: 0.00229 D-glucopyranose_6-phosphate + 0.01887 D-ribose_5-phosphate + 0.01032 D-erythrose_4-phosphate + 0.05595 phosphoenolpyruvate + 0.07365 pyruvate + 0.07501 acetyl-CoA + 0.02737 2-oxoglutarate + 0.04016 oxaloacetate + 0.99685 ATP + 0.47126 NADPH + 0.17027 N_GLU + 0.06727 N_GLN + 0.00398 polyhydroxybutyrate_produced + 0.0009 L-ornithine + 0.0824 NAD+ + 0.99685 H2O = biomass_2 + 0.0824 NADH + 0.00611 CO2 + 0.99685 phosphate + 0.99685 ADP + 0.07501 coenzyme_A + 1.31071 H+ + 0.47126 NADP+
B7: biomass_typeII 4.2GAM | C7: 0.00229 D-glucopyranose_6-phosphate + 0.01887 D-ribose_5-phosphate + 0.01032 D-erythrose_4-phosphate + 0.05595 phosphoenolpyruvate + 0.07365 pyruvate + 0.07501 acetyl-CoA + 0.02737 2-oxoglutarate + 0.04016 oxaloacetate + 1.51345 ATP + 0.47126 NADPH + 0.17027 N_GLU + 0.06727 N_GLN + 0.00398 polyhydroxybutyrate_produced + 0.0009 L-ornithine + 0.0824 NAD+ + 1.51345 H2O = biomass_2 + 0.0824 NADH + 0.00611 CO2 + 1.51345 phosphate + 1.51345 ADP + 0.07501 coenzyme_A + 1.82731 H+ + 0.47126 NADP+
B9: biomass typeII 4.4 GAM | C9: 0.00229 D-glucopyranose_6-phosphate + 0.01887 D-ribose_5-phosphate + 0.01032 D-erythrose_4-phosphate + 0.05595 phosphoenolpyruvate + 0.07365 pyruvate + 0.07501 acetyl-CoA + 0.02737 2-oxoglutarate + 0.04016 oxaloacetate + 1.51345 ATP + 0.57029 NADPH + 0.17027 N_GLU + 0.06727 N_GLN + 0.00398 polyhydroxybutyrate_produced + 0.0009 L-ornithine + 0.0824 NAD+ + 1.51345 H2O = biomass_2 + 0.0824 NADH + 0.00611 CO2 + 1.51345 phosphate + 1.51345 ADP + 0.07501 coenzyme_A + 1.82731 H+ + 0.57029 NADP+
B10: biomass typeII 4.6 GAM | C10: 0.00229 D-glucopyranose_6-phosphate + 0.01887 D-ribose_5-phosphate + 0.01032 D-erythrose_4-phosphate + 0.05595 phosphoenolpyruvate + 0.07365 pyruvate + 0.07501 acetyl-CoA + 0.02737 2-oxoglutarate + 0.04016 oxaloacetate + 1.51345 ATP + 0.67001 NADPH + 0.17027 N_GLU + 0.06727 N_GLN + 0.00398 polyhydroxybutyrate_produced + 0.0009 L-ornithine + 0.0824 NAD+ + 1.51345 H2O = biomass_2 + 0.0824 NADH + 0.00611 CO2 + 1.51345 phosphate + 1.51345 ADP + 0.07501 coenzyme_A + 1.82731 H+ + 0.67001 NADP+
